<robot
  name="rescue_robot_arm.SLDASM">
  <link
    name="base_link">
    <inertial>
      <origin
        xyz="0.24824 -0.066844 0.19422"
        rpy="0 0 0" />
      <mass
        value="0.38823" />
      <inertia
        ixx="0.00043224"
        ixy="-7.4607E-06"
        ixz="-8.4129E-07"
        iyy="0.00041417"
        iyz="-1.4996E-06"
        izz="0.00034463" />
    </inertial>
    <visual>
      <origin
        xyz="0 0 0"
        rpy="0 0 0" />
      <geometry>
        <mesh
          filename="package://rescue_robot_arm.SLDASM/meshes/base_link.stl" />
      </geometry>
      <material
        name="">
        <color
          rgba="0.86667 0.9098 1 1" />
      </material>
    </visual>
    <collision>
      <origin
        xyz="0 0 0"
        rpy="0 0 0" />
      <geometry>
        <mesh
          filename="package://rescue_robot_arm.SLDASM/meshes/base_link.stl" />
      </geometry>
    </collision>
  </link>
  <link
    name="ARM_PTZ_Link">
    <inertial>
      <origin
        xyz="0.037138 -0.026294 0.034984"
        rpy="0 0 0" />
      <mass
        value="0.10397" />
      <inertia
        ixx="8.0981E-05"
        ixy="4.603E-06"
        ixz="-3.4851E-09"
        iyy="9.211E-05"
        iyz="3.1711E-08"
        izz="9.582E-05" />
    </inertial>
    <visual>
      <origin
        xyz="0 0 0"
        rpy="0 0 0" />
      <geometry>
        <mesh
          filename="package://rescue_robot_arm.SLDASM/meshes/ARM_PTZ_Link.stl" />
      </geometry>
      <material
        name="">
        <color
          rgba="0.29412 0.29412 0.29412 1" />
      </material>
    </visual>
    <collision>
      <origin
        xyz="0 0 0"
        rpy="0 0 0" />
      <geometry>
        <mesh
          filename="package://rescue_robot_arm.SLDASM/meshes/ARM_PTZ_Link.stl" />
      </geometry>
    </collision>
  </link>
  <joint
    name="ARM_PTZ_Joint"
    type="continuous">
    <origin
      xyz="0.22077 -0.158 -0.033667"
      rpy="-1.5708 -6.123E-17 -1.5708" />
    <parent
      link="base_link" />
    <child
      link="ARM_PTZ_Link" />
    <axis
      xyz="0 1 0" />
  </joint>
  <link
    name="ARM_Joint1_Link">
    <inertial>
      <origin
        xyz="-0.093428 -6.7766E-09 -0.22285"
        rpy="0 0 0" />
      <mass
        value="0.33655" />
      <inertia
        ixx="0.011329"
        ixy="-7.6342E-11"
        ixz="-1.0332E-06"
        iyy="0.011497"
        iyz="-5.1113E-08"
        izz="0.00030224" />
    </inertial>
    <visual>
      <origin
        xyz="0 0 0"
        rpy="0 0 0" />
      <geometry>
        <mesh
          filename="package://rescue_robot_arm.SLDASM/meshes/ARM_Joint1_Link.stl" />
      </geometry>
      <material
        name="">
        <color
          rgba="0.29412 0.29412 0.29412 1" />
      </material>
    </visual>
    <collision>
      <origin
        xyz="0 0 0"
        rpy="0 0 0" />
      <geometry>
        <mesh
          filename="package://rescue_robot_arm.SLDASM/meshes/ARM_Joint1_Link.stl" />
      </geometry>
    </collision>
  </link>
  <joint
    name="ARM_Joint1"
    type="revolute">
    <origin
      xyz="0.072 -0.047 0.035"
      rpy="-1.5708 0 0" />
    <parent
      link="ARM_PTZ_Link" />
    <child
      link="ARM_Joint1_Link" />
    <axis
      xyz="1 0 0" />
		<limit
			effort="1000.0"
			lower="-1.8"
			upper="1.7"
			velocity="0.5" />
  </joint>
  <link
    name="ARM_Joint2_Link">
    <inertial>
      <origin
        xyz="0.23841 0.040319 0.0063346"
        rpy="0 0 0" />
      <mass
        value="0.31983" />
      <inertia
        ixx="0.00040584"
        ixy="-4.4847E-05"
        ixz="0.00035965"
        iyy="0.0098258"
        iyz="-1.5156E-06"
        izz="0.0096005" />
    </inertial>
    <visual>
      <origin
        xyz="0 0 0"
        rpy="0 0 0" />
      <geometry>
        <mesh
          filename="package://rescue_robot_arm.SLDASM/meshes/ARM_Joint2_Link.stl" />
      </geometry>
      <material
        name="">
        <color
          rgba="0.29412 0.29412 0.29412 1" />
      </material>
    </visual>
    <collision>
      <origin
        xyz="0 0 0"
        rpy="0 0 0" />
      <geometry>
        <mesh
          filename="package://rescue_robot_arm.SLDASM/meshes/ARM_Joint2_Link.stl" />
      </geometry>
    </collision>
  </link>
  <joint
    name="ARM_Joint2"
    type="revolute">
    <origin
      xyz="0.004 0 -0.446"
      rpy="3.1416 -1.7347E-16 -1.5708" />
    <parent
      link="ARM_Joint1_Link" />
    <child
      link="ARM_Joint2_Link" />
    <axis
      xyz="0 1 0" />
		<limit
			effort="1000.0"
			lower="-1.5"
			upper="1.5"
			velocity="0.5" />
  </joint>
  <link
    name="ARM_PITCH_Link">
    <inertial>
      <origin
        xyz="-0.0078216 -0.031669 0.034896"
        rpy="0 0 0" />
      <mass
        value="0.24177" />
      <inertia
        ixx="0.00069778"
        ixy="-1.3365E-05"
        ixz="-2.3292E-05"
        iyy="0.00058522"
        iyz="-2.3183E-05"
        izz="0.0003799" />
    </inertial>
    <visual>
      <origin
        xyz="0 0 0"
        rpy="0 0 0" />
      <geometry>
        <mesh
          filename="package://rescue_robot_arm.SLDASM/meshes/ARM_PITCH_Link.stl" />
      </geometry>
      <material
        name="">
        <color
          rgba="0.29412 0.29412 0.29412 1" />
      </material>
    </visual>
    <collision>
      <origin
        xyz="0 0 0"
        rpy="0 0 0" />
      <geometry>
        <mesh
          filename="package://rescue_robot_arm.SLDASM/meshes/ARM_PITCH_Link.stl" />
      </geometry>
    </collision>
  </link>
  <joint
    name="ARM_PITCH_Joint"
    type="revolute">
    <origin
      xyz="0.4 0.10395 0.05"
      rpy="1.5708 0 1.5708" />
    <parent
      link="ARM_Joint2_Link" />
    <child
      link="ARM_PITCH_Link" />
    <axis
      xyz="1 0 0" />
		<limit
			effort="1000.0"
			lower="-1.5"
			upper="1.5"
			velocity="0.5" />
  </joint>
  <link
    name="ARM_ROLL_Link">
    <inertial>
      <origin
        xyz="-0.00082833 -0.0025054 0.0014655"
        rpy="0 0 0" />
      <mass
        value="0.016482" />
      <inertia
        ixx="9.8809E-06"
        ixy="-3.081E-08"
        ixz="-1.456E-07"
        iyy="1.1293E-06"
        iyz="5.6573E-08"
        izz="1.0056E-05" />
    </inertial>
    <visual>
      <origin
        xyz="0 0 0"
        rpy="0 0 0" />
      <geometry>
        <mesh
          filename="package://rescue_robot_arm.SLDASM/meshes/ARM_ROLL_Link.stl" />
      </geometry>
      <material
        name="">
        <color
          rgba="0.29412 0.29412 0.29412 1" />
      </material>
    </visual>
    <collision>
      <origin
        xyz="0 0 0"
        rpy="0 0 0" />
      <geometry>
        <mesh
          filename="package://rescue_robot_arm.SLDASM/meshes/ARM_ROLL_Link.stl" />
      </geometry>
    </collision>
  </link>
  <joint
    name="ARM_ROLL_Joint"
    type="continuous">
    <origin
      xyz="0.002 -0.048 0.12965"
      rpy="1.5708 0 0.51512" />
    <parent
      link="ARM_PITCH_Link" />
    <child
      link="ARM_ROLL_Link" />
    <axis
      xyz="0 1 0" />
  </joint>
  <link
    name="ARM_GRIPPER_Link">
    <inertial>
      <origin
        xyz="-0.00020866 -0.096293 0.007"
        rpy="0 0 0" />
      <mass
        value="0.11066" />
      <inertia
        ixx="0.00051307"
        ixy="5.1477E-06"
        ixz="7.3922E-13"
        iyy="0.00013176"
        iyz="-3.3013E-11"
        izz="0.00063018" />
    </inertial>
    <visual>
      <origin
        xyz="0 0 0"
        rpy="0 0 0" />
      <geometry>
        <mesh
          filename="package://rescue_robot_arm.SLDASM/meshes/ARM_GRIPPER_Link.stl" />
      </geometry>
      <material
        name="">
        <color
          rgba="0.29412 0.29412 0.29412 1" />
      </material>
    </visual>
    <collision>
      <origin
        xyz="0 0 0"
        rpy="0 0 0" />
      <geometry>
        <mesh
          filename="package://rescue_robot_arm.SLDASM/meshes/ARM_GRIPPER_Link.stl" />
      </geometry>
    </collision>
  </link>
  <joint
    name="ARM_GRIPPER_Joint"
    type="prismatic">
    <origin
      xyz="-0.054509 0.072845 0.082079"
      rpy="1.0556 0.011745 1.5641" />
    <parent
      link="ARM_ROLL_Link" />
    <child
      link="ARM_GRIPPER_Link" />
    <axis
      xyz="1 0 0" />
		<limit
			effort="1000.0"
			lower="-0.04"
			upper="0.0"
			velocity="0.5" />
  </joint>
</robot>
